Workbook
Name RunIDs: 'Run Index'!$A$6:$A$205

Sheet Start Here
B2: HALF-CAR ITERATION TRACKER
B5: A lightweight, offline notebook for inputs, outputs, graphs and engineering decisions. No macros, accounts, server, or external workbook connections.
B9: 1 Choose an ID
B10: Use RUN-001, RUN-002, etc. The same IDs are already present on all main sheets. RUN-001 contains input examples only: it is marked Template / not run, with no outputs. Change its record type only after a real run.
B13: 2 Record the reason
B14: In Run Index enter the name, timestamp/timezone, parent ID, code version, exactly what changed, and the loading condition. Never overwrite a completed run to try a new setting.
B17: 3 Fill the inputs
B18: Use Vehicle Inputs and Road and Solver. Blue cells accept values; grey cells calculate. Rates are wheel-equivalent and SI units are in every header. Record actual values, not only the intended values.
B21: 4 Describe every bump
B22: Use Bumps: one row per active bump, numbered 1 through N. Enter height, width, and the flat gap after each bump except the last. Zero gaps mean touching bumps. Filter by Run ID to review the sequence.
B25: 5 Run MATLAB
B26: This workbook is a manual log, not a simulation or automatic MATLAB importer. Run the model, then copy its eight Value metrics into Outputs using m and rad as shown. The workbook also displays mm and degrees.
... B59: Open Field Guide

Sheet Run Index
A1: ITERATION REGISTER
A2: One record per run. Blue = enter data; grey = calculated. IDs are preassigned across the input/output sheets; keep each ID with its data when sorting. A blank output is unknown, never a pass.
A5: Run ID | B5: Run name | C5: Date / time (with timezone) | D5: Owner | E5: Record type | F5: Parent / baseline ID | G5: What changed? | H5: Hypothesis / expected effect | I5: Code commit / version | J5: Driver / fuel / payload condition | K5: Parameter source / uncertainty | L5: Results folder path / URL | M5: Dashboard image path / URL | N5: MAT data / CSV path / URL | O5: Decision / next action | P5: Open folder | Q5: Open graph
A6: RUN-001 | B6: Template: repository defaults | E6: Template / not run | G6: Starting input example only; run MATLAB before entering outputs. | I6: 91a3718 (input baseline) | P6: =IF(L6="","",HYPERLINK(L6,"Open folder")) | Q6: =IF(M6="","",HYPERLINK(M6,"Open dashboard"))
A7: RUN-002 | P7: =IF(L7="","",HYPERLINK(L7,"Open folder")) | Q7: =IF(M7="","",HYPERLINK(M7,"Open dashboard"))
A8: RUN-003 | P8: =IF(L8="","",HYPERLINK(L8,"Open folder")) | Q8: =IF(M8="","",HYPERLINK(M8,"Open dashboard"))
A9: RUN-004 | P9: =IF(L9="","",HYPERLINK(L9,"Open folder")) | Q9: =IF(M9="","",HYPERLINK(M9,"Open dashboard"))
A10: RUN-005 | P10: =IF(L10="","",HYPERLINK(L10,"Open folder")) | Q10: =IF(M10="","",HYPERLINK(M10,"Open dashboard"))
A11: RUN-006 | P11: =IF(L11="","",HYPERLINK(L11,"Open folder")) | Q11: =IF(M11="","",HYPERLINK(M11,"Open dashboard"))
A12: RUN-007 | P12: =IF(L12="","",HYPERLINK(L12,"Open folder")) | Q12: =IF(M12="","",HYPERLINK(M12,"Open dashboard"))
A13: RUN-008 | P13: =IF(L13="","",HYPERLINK(L13,"Open folder")) | Q13: =IF(M13="","",HYPERLINK(M13,"Open dashboard"))
A14: RUN-009 | P14: =IF(L14="","",HYPERLINK(L14,"Open folder")) | Q14: =IF(M14="","",HYPERLINK(M14,"Open dashboard"))
A15: RUN-010 | P15: =IF(L15="","",HYPERLINK(L15,"Open folder")) | Q15: =IF(M15="","",HYPERLINK(M15,"Open dashboard"))
A16: RUN-011 | P16: =IF(L16="","",HYPERLINK(L16,"Open folder")) | Q16: =IF(M16="","",HYPERLINK(M16,"Open dashboard"))
A17: RUN-012 | P17: =IF(L17="","",HYPERLINK(L17,"Open folder")) | Q17: =IF(M17="","",HYPERLINK(M17,"Open dashboard"))
A18: RUN-013 | P18: =IF(L18="","",HYPERLINK(L18,"Open folder")) | Q18: =IF(M18="","",HYPERLINK(M18,"Open dashboard"))
... A205: RUN-200 | P205: =IF(L205="","",HYPERLINK(L205,"Open folder")) | Q205: =IF(M205="","",HYPERLINK(M205,"Open dashboard"))

Sheet Vehicle Inputs
A1: VEHICLE INPUTS
A2: Use actual wheel-equivalent rates. One-side and axle-equivalent mass/property conventions must not be mixed. First row contains unvalidated repository examples; other rows are blank.
A5: Run ID | B5: Mass convention | C5: m: sprung mass [kg] | D5: m1: front unsprung [kg] | E5: m2: rear unsprung [kg] | F5: Iy: sprung pitch inertia [kg m^2] | G5: a1: CG to front [m] | H5: a2: CG to rear [m] | I5: k1: front WHEEL rate [N/m] | J5: k2: rear WHEEL rate [N/m] | K5: c1: front WHEEL damping [N s/m] | L5: c2: rear WHEEL damping [N s/m] | M5: kt1: front tire rate [N/m] | N5: kt2: rear tire rate [N/m] | O5: Front tire pressure [kPa] | P5: Rear tire pressure [kPa] | Q5: Wheelbase [m] | R5: Static front load estimate [N] | S5: Static rear load estimate [N]
A6: RUN-001 | B6: Unconfirmed | C6: 420 | D6: 53 | E6: 76 | F6: 1100 | G6: 1.4 | H6: 1.47 | I6: 10000 | J6: 13000 | K6: 10000 | L6: 10000 | M6: 200000 | N6: 200000 | Q6: =IF(COUNT(G6:H6)<2,"",G6+H6) | R6: =IF(OR(COUNT(C6:E6,G6:H6)<5,SUM(G6:H6)<=0),"",9.81*(C6*H6/SUM(G6:H6)+D6)) | S6: =IF(OR(COUNT(C6:E6,G6:H6)<5,SUM(G6:H6)<=0),"",9.81*(C6*G6/SUM(G6:H6)+E6))
A7: RUN-002 | Q7: =IF(COUNT(G7:H7)<2,"",G7+H7) | R7: =IF(OR(COUNT(C7:E7,G7:H7)<5,SUM(G7:H7)<=0),"",9.81*(C7*H7/SUM(G7:H7)+D7)) | S7: =IF(OR(COUNT(C7:E7,G7:H7)<5,SUM(G7:H7)<=0),"",9.81*(C7*G7/SUM(G7:H7)+E7))
A8: RUN-003 | Q8: =IF(COUNT(G8:H8)<2,"",G8+H8) | R8: =IF(OR(COUNT(C8:E8,G8:H8)<5,SUM(G8:H8)<=0),"",9.81*(C8*H8/SUM(G8:H8)+D8)) | S8: =IF(OR(COUNT(C8:E8,G8:H8)<5,SUM(G8:H8)<=0),"",9.81*(C8*G8/SUM(G8:H8)+E8))
A9: RUN-004 | Q9: =IF(COUNT(G9:H9)<2,"",G9+H9) | R9: =IF(OR(COUNT(C9:E9,G9:H9)<5,SUM(G9:H9)<=0),"",9.81*(C9*H9/SUM(G9:H9)+D9)) | S9: =IF(OR(COUNT(C9:E9,G9:H9)<5,SUM(G9:H9)<=0),"",9.81*(C9*G9/SUM(G9:H9)+E9))
A10: RUN-005 | Q10: =IF(COUNT(G10:H10)<2,"",G10+H10) | R10: =IF(OR(COUNT(C10:E10,G10:H10)<5,SUM(G10:H10)<=0),"",9.81*(C10*H10/SUM(G10:H10)+D10)) | S10: =IF(OR(COUNT(C10:E10,G10:H10)<5,SUM(G10:H10)<=0),"",9.81*(C10*G10/SUM(G10:H10)+E10))
A11: RUN-006 | Q11: =IF(COUNT(G11:H11)<2,"",G11+H11) | R11: =IF(OR(COUNT(C11:E11,G11:H11)<5,SUM(G11:H11)<=0),"",9.81*(C11*H11/SUM(G11:H11)+D11)) | S11: =IF(OR(COUNT(C11:E11,G11:H11)<5,SUM(G11:H11)<=0),"",9.81*(C11*G11/SUM(G11:H11)+E11))
A12: RUN-007 | Q12: =IF(COUNT(G12:H12)<2,"",G12+H12) | R12: =IF(OR(COUNT(C12:E12,G12:H12)<5,SUM(G12:H12)<=0),"",9.81*(C12*H12/SUM(G12:H12)+D12)) | S12: =IF(OR(COUNT(C12:E12,G12:H12)<5,SUM(G12:H12)<=0),"",9.81*(C12*G12/SUM(G12:H12)+E12))
A13: RUN-008 | Q13: =IF(COUNT(G13:H13)<2,"",G13+H13) | R13: =IF(OR(COUNT(C13:E13,G13:H13)<5,SUM(G13:H13)<=0),"",9.81*(C13*H13/SUM(G13:H13)+D13)) | S13: =IF(OR(COUNT(C13:E13,G13:H13)<5,SUM(G13:H13)<=0),"",9.81*(C13*G13/SUM(G13:H13)+E13))
A14: RUN-009 | Q14: =IF(COUNT(G14:H14)<2,"",G14+H14) | R14: =IF(OR(COUNT(C14:E14,G14:H14)<5,SUM(G14:H14)<=0),"",9.81*(C14*H14/SUM(G14:H14)+D14)) | S14: =IF(OR(COUNT(C14:E14,G14:H14)<5,SUM(G14:H14)<=0),"",9.81*(C14*G14/SUM(G14:H14)+E14))
A15: RUN-010 | Q15: =IF(COUNT(G15:H15)<2,"",G15+H15) | R15: =IF(OR(COUNT(C15:E15,G15:H15)<5,SUM(G15:H15)<=0),"",9.81*(C15*H15/SUM(G15:H15)+D15)) | S15: =IF(OR(COUNT(C15:E15,G15:H15)<5,SUM(G15:H15)<=0),"",9.81*(C15*G15/SUM(G15:H15)+E15))
A16: RUN-011 | Q16: =IF(COUNT(G16:H16)<2,"",G16+H16) | R16: =IF(OR(COUNT(C16:E16,G16:H16)<5,SUM(G16:H16)<=0),"",9.81*(C16*H16/SUM(G16:H16)+D16)) | S16: =IF(OR(COUNT(C16:E16,G16:H16)<5,SUM(G16:H16)<=0),"",9.81*(C16*G16/SUM(G16:H16)+E16))
A17: RUN-012 | Q17: =IF(COUNT(G17:H17)<2,"",G17+H17) | R17: =IF(OR(COUNT(C17:E17,G17:H17)<5,SUM(G17:H17)<=0),"",9.81*(C17*H17/SUM(G17:H17)+D17)) | S17: =IF(OR(COUNT(C17:E17,G17:H17)<5,SUM(G17:H17)<=0),"",9.81*(C17*G17/SUM(G17:H17)+E17))
A18: RUN-013 | Q18: =IF(COUNT(G18:H18)<2,"",G18+H18) | R18: =IF(OR(COUNT(C18:E18,G18:H18)<5,SUM(G18:H18)<=0),"",9.81*(C18*H18/SUM(G18:H18)+D18)) | S18: =IF(OR(COUNT(C18:E18,G18:H18)<5,SUM(G18:H18)<=0),"",9.81*(C18*G18/SUM(G18:H18)+E18))
... A205: RUN-200 | Q205: =IF(COUNT(G205:H205)<2,"",G205+H205) | R205: =IF(OR(COUNT(C205:E205,G205:H205)<5,SUM(G205:H205)<=0),"",9.81*(C205*H205/SUM(G205:H205)+D205)) | S205: =IF(OR(COUNT(C205:E205,G205:H205)<5,SUM(G205:H205)<=0),"",9.81*(C205*G205/SUM(G205:H205)+E205))

Sheet Road and Solver
A1: ROAD, SOLVER & DISPLAY
A2: Enter every active bump in Bumps. Solver timing is independent of playback. Absolute tolerance order: body displacement, pitch, acceleration, front/rear travel, front/rear minimum loads, RMS acceleration.
A5: Run ID | B5: Speed [m/s] | C5: Bump shape | D5: Consecutive bumps? | E5: Requested simulation_dt [s] | F5: Actual simulation_dt [s] | G5: Requested minimum tF [s] | H5: Actual end time [s] | I5: post_bump_time [s] | J5: Convergence requested? | K5: Relative tolerance [fraction] | L5: Absolute tolerances [table order] | M5: Initial flat length [m] | N5: Initial road dx [m] | O5: Trailing flat length used [m] | P5: Trailing road dx [m] | Q5: Bump count (from Bumps) | R5: Playback speed | S5: Video FPS | T5: Animation enabled? | U5: Video enabled? | V5: Video filename / path
A6: RUN-001 | B6: 10 | C6: cosine | D6: no | E6: 0.001 | G6: 1 | I6: 1 | J6: yes | K6: 0.01 | L6: [1e-5 1e-5 0.01 1e-5 1e-5 1 1 0.01] | M6: 5 | N6: 0.1 | P6: 0.1 | Q6: =COUNTIFS(Bumps!$A$6:$A$2005,A6,Bumps!$C$6:$C$2005,"<>",Bumps!$D$6:$D$2005,"<>") -> 0 | R6: 0.1 | S6: 30 | T6: yes | U6: yes | V6: half_car_model.mp4
A7: RUN-002 | Q7: =COUNTIFS(Bumps!$A$6:$A$2005,A7,Bumps!$C$6:$C$2005,"<>",Bumps!$D$6:$D$2005,"<>") -> 0
A8: RUN-003 | Q8: =COUNTIFS(Bumps!$A$6:$A$2005,A8,Bumps!$C$6:$C$2005,"<>",Bumps!$D$6:$D$2005,"<>") -> 0
A9: RUN-004 | Q9: =COUNTIFS(Bumps!$A$6:$A$2005,A9,Bumps!$C$6:$C$2005,"<>",Bumps!$D$6:$D$2005,"<>") -> 0
A10: RUN-005 | Q10: =COUNTIFS(Bumps!$A$6:$A$2005,A10,Bumps!$C$6:$C$2005,"<>",Bumps!$D$6:$D$2005,"<>") -> 0
A11: RUN-006 | Q11: =COUNTIFS(Bumps!$A$6:$A$2005,A11,Bumps!$C$6:$C$2005,"<>",Bumps!$D$6:$D$2005,"<>") -> 0
A12: RUN-007 | Q12: =COUNTIFS(Bumps!$A$6:$A$2005,A12,Bumps!$C$6:$C$2005,"<>",Bumps!$D$6:$D$2005,"<>") -> 0
A13: RUN-008 | Q13: =COUNTIFS(Bumps!$A$6:$A$2005,A13,Bumps!$C$6:$C$2005,"<>",Bumps!$D$6:$D$2005,"<>") -> 0
A14: RUN-009 | Q14: =COUNTIFS(Bumps!$A$6:$A$2005,A14,Bumps!$C$6:$C$2005,"<>",Bumps!$D$6:$D$2005,"<>") -> 0
A15: RUN-010 | Q15: =COUNTIFS(Bumps!$A$6:$A$2005,A15,Bumps!$C$6:$C$2005,"<>",Bumps!$D$6:$D$2005,"<>") -> 0
A16: RUN-011 | Q16: =COUNTIFS(Bumps!$A$6:$A$2005,A16,Bumps!$C$6:$C$2005,"<>",Bumps!$D$6:$D$2005,"<>") -> 0
A17: RUN-012 | Q17: =COUNTIFS(Bumps!$A$6:$A$2005,A17,Bumps!$C$6:$C$2005,"<>",Bumps!$D$6:$D$2005,"<>") -> 0
A18: RUN-013 | Q18: =COUNTIFS(Bumps!$A$6:$A$2005,A18,Bumps!$C$6:$C$2005,"<>",Bumps!$D$6:$D$2005,"<>") -> 0
... A205: RUN-200 | Q205: =COUNTIFS(Bumps!$A$6:$A$2005,A205,Bumps!$C$6:$C$2005,"<>",Bumps!$D$6:$D$2005,"<>") -> 0

Sheet Bumps
A1: BUMP-BY-BUMP ROAD DEFINITION
A2: One row per active bump. Use consecutive numbers starting at 1. N bumps need N−1 gaps: leave the final gap blank. Zero means touching bumps; a blank internal gap is missing data. Same structure is used for a single bump.
A5: Run ID | B5: Bump number | C5: Height [m] | D5: Width along road [m] | E5: Flat gap AFTER bump [m] | F5: Profile / measurement notes | G5: Duplicate ID + number?
A6: RUN-001 | B6: 1 | C6: 0.2 | D6: 0.4 | G6: =IF(OR(A6="",B6=""),"",IF(COUNTIFS($A$6:$A$2005,A6,$B$6:$B$2005,B6)>1,"DUPLICATE",""))
G7: =IF(OR(A7="",B7=""),"",IF(COUNTIFS($A$6:$A$2005,A7,$B$6:$B$2005,B7)>1,"DUPLICATE",""))
G8: =IF(OR(A8="",B8=""),"",IF(COUNTIFS($A$6:$A$2005,A8,$B$6:$B$2005,B8)>1,"DUPLICATE",""))
G9: =IF(OR(A9="",B9=""),"",IF(COUNTIFS($A$6:$A$2005,A9,$B$6:$B$2005,B9)>1,"DUPLICATE",""))
G10: =IF(OR(A10="",B10=""),"",IF(COUNTIFS($A$6:$A$2005,A10,$B$6:$B$2005,B10)>1,"DUPLICATE",""))
G11: =IF(OR(A11="",B11=""),"",IF(COUNTIFS($A$6:$A$2005,A11,$B$6:$B$2005,B11)>1,"DUPLICATE",""))
G12: =IF(OR(A12="",B12=""),"",IF(COUNTIFS($A$6:$A$2005,A12,$B$6:$B$2005,B12)>1,"DUPLICATE",""))
G13: =IF(OR(A13="",B13=""),"",IF(COUNTIFS($A$6:$A$2005,A13,$B$6:$B$2005,B13)>1,"DUPLICATE",""))
G14: =IF(OR(A14="",B14=""),"",IF(COUNTIFS($A$6:$A$2005,A14,$B$6:$B$2005,B14)>1,"DUPLICATE",""))
G15: =IF(OR(A15="",B15=""),"",IF(COUNTIFS($A$6:$A$2005,A15,$B$6:$B$2005,B15)>1,"DUPLICATE",""))
G16: =IF(OR(A16="",B16=""),"",IF(COUNTIFS($A$6:$A$2005,A16,$B$6:$B$2005,B16)>1,"DUPLICATE",""))
G17: =IF(OR(A17="",B17=""),"",IF(COUNTIFS($A$6:$A$2005,A17,$B$6:$B$2005,B17)>1,"DUPLICATE",""))
G18: =IF(OR(A18="",B18=""),"",IF(COUNTIFS($A$6:$A$2005,A18,$B$6:$B$2005,B18)>1,"DUPLICATE",""))
... G2005: =IF(OR(A2005="",B2005=""),"",IF(COUNTIFS($A$6:$A$2005,A2005,$B$6:$B$2005,B2005)>1,"DUPLICATE",""))

Sheet Outputs
A1: OUTPUTS & CONFIDENCE
A2: Paste the eight Value metrics from MATLAB using the SI units shown. Leave unknown values blank. Blue cells are manual records; grey cells convert units or screen contact. A convergence pass does not validate the physics.
A5: Run ID | B5: Peak abs body displacement [m] | C5: Peak abs pitch [rad] | D5: Peak abs body acceleration [m/s^2] | E5: Peak abs front travel [m] | F5: Peak abs rear travel [m] | G5: Minimum front tire load [N] | H5: Minimum rear tire load [N] | I5: RMS body acceleration [m/s^2] | J5: RMS interval / definition | K5: Convergence result | L5: First contact violation [s] | M5: Physical validation status | N5: Interpretation / trade-off | O5: Peak body displacement [mm] | P5: Peak pitch [deg] | Q5: Peak front travel [mm] | R5: Peak rear travel [mm] | S5: Contact screen (calculated)
A6: RUN-001 | J6: Whole simulation: 0 to actual end time | K6: Not checked | M6: Not validated | O6: =IF(ISNUMBER(B6),B6*1000,"") | P6: =IF(ISNUMBER(C6),C6*180/PI(),"") | Q6: =IF(ISNUMBER(E6),E6*1000,"") | R6: =IF(ISNUMBER(F6),F6*1000,"") | S6: =IF(OR(AND(ISNUMBER(G6),G6<0),AND(ISNUMBER(H6),H6<0)),"VIOLATED - later response unreliable",IF(COUNT(G6:H6)=2,"No negative predicted (estimate)","Not entered / incomplete")) -> Not entered / incomplete
A7: RUN-002 | O7: =IF(ISNUMBER(B7),B7*1000,"") | P7: =IF(ISNUMBER(C7),C7*180/PI(),"") | Q7: =IF(ISNUMBER(E7),E7*1000,"") | R7: =IF(ISNUMBER(F7),F7*1000,"") | S7: =IF(OR(AND(ISNUMBER(G7),G7<0),AND(ISNUMBER(H7),H7<0)),"VIOLATED - later response unreliable",IF(COUNT(G7:H7)=2,"No negative predicted (estimate)","Not entered / incomplete")) -> Not entered / incomplete
A8: RUN-003 | O8: =IF(ISNUMBER(B8),B8*1000,"") | P8: =IF(ISNUMBER(C8),C8*180/PI(),"") | Q8: =IF(ISNUMBER(E8),E8*1000,"") | R8: =IF(ISNUMBER(F8),F8*1000,"") | S8: =IF(OR(AND(ISNUMBER(G8),G8<0),AND(ISNUMBER(H8),H8<0)),"VIOLATED - later response unreliable",IF(COUNT(G8:H8)=2,"No negative predicted (estimate)","Not entered / incomplete")) -> Not entered / incomplete
A9: RUN-004 | O9: =IF(ISNUMBER(B9),B9*1000,"") | P9: =IF(ISNUMBER(C9),C9*180/PI(),"") | Q9: =IF(ISNUMBER(E9),E9*1000,"") | R9: =IF(ISNUMBER(F9),F9*1000,"") | S9: =IF(OR(AND(ISNUMBER(G9),G9<0),AND(ISNUMBER(H9),H9<0)),"VIOLATED - later response unreliable",IF(COUNT(G9:H9)=2,"No negative predicted (estimate)","Not entered / incomplete")) -> Not entered / incomplete
A10: RUN-005 | O10: =IF(ISNUMBER(B10),B10*1000,"") | P10: =IF(ISNUMBER(C10),C10*180/PI(),"") | Q10: =IF(ISNUMBER(E10),E10*1000,"") | R10: =IF(ISNUMBER(F10),F10*1000,"") | S10: =IF(OR(AND(ISNUMBER(G10),G10<0),AND(ISNUMBER(H10),H10<0)),"VIOLATED - later response unreliable",IF(COUNT(G10:H10)=2,"No negative predicted (estimate)","Not entered / incomplete")) -> Not entered / incomplete
A11: RUN-006 | O11: =IF(ISNUMBER(B11),B11*1000,"") | P11: =IF(ISNUMBER(C11),C11*180/PI(),"") | Q11: =IF(ISNUMBER(E11),E11*1000,"") | R11: =IF(ISNUMBER(F11),F11*1000,"") | S11: =IF(OR(AND(ISNUMBER(G11),G11<0),AND(ISNUMBER(H11),H11<0)),"VIOLATED - later response unreliable",IF(COUNT(G11:H11)=2,"No negative predicted (estimate)","Not entered / incomplete")) -> Not entered / incomplete
A12: RUN-007 | O12: =IF(ISNUMBER(B12),B12*1000,"") | P12: =IF(ISNUMBER(C12),C12*180/PI(),"") | Q12: =IF(ISNUMBER(E12),E12*1000,"") | R12: =IF(ISNUMBER(F12),F12*1000,"") | S12: =IF(OR(AND(ISNUMBER(G12),G12<0),AND(ISNUMBER(H12),H12<0)),"VIOLATED - later response unreliable",IF(COUNT(G12:H12)=2,"No negative predicted (estimate)","Not entered / incomplete")) -> Not entered / incomplete
A13: RUN-008 | O13: =IF(ISNUMBER(B13),B13*1000,"") | P13: =IF(ISNUMBER(C13),C13*180/PI(),"") | Q13: =IF(ISNUMBER(E13),E13*1000,"") | R13: =IF(ISNUMBER(F13),F13*1000,"") | S13: =IF(OR(AND(ISNUMBER(G13),G13<0),AND(ISNUMBER(H13),H13<0)),"VIOLATED - later response unreliable",IF(COUNT(G13:H13)=2,"No negative predicted (estimate)","Not entered / incomplete")) -> Not entered / incomplete
A14: RUN-009 | O14: =IF(ISNUMBER(B14),B14*1000,"") | P14: =IF(ISNUMBER(C14),C14*180/PI(),"") | Q14: =IF(ISNUMBER(E14),E14*1000,"") | R14: =IF(ISNUMBER(F14),F14*1000,"") | S14: =IF(OR(AND(ISNUMBER(G14),G14<0),AND(ISNUMBER(H14),H14<0)),"VIOLATED - later response unreliable",IF(COUNT(G14:H14)=2,"No negative predicted (estimate)","Not entered / incomplete")) -> Not entered / incomplete
A15: RUN-010 | O15: =IF(ISNUMBER(B15),B15*1000,"") | P15: =IF(ISNUMBER(C15),C15*180/PI(),"") | Q15: =IF(ISNUMBER(E15),E15*1000,"") | R15: =IF(ISNUMBER(F15),F15*1000,"") | S15: =IF(OR(AND(ISNUMBER(G15),G15<0),AND(ISNUMBER(H15),H15<0)),"VIOLATED - later response unreliable",IF(COUNT(G15:H15)=2,"No negative predicted (estimate)","Not entered / incomplete")) -> Not entered / incomplete
A16: RUN-011 | O16: =IF(ISNUMBER(B16),B16*1000,"") | P16: =IF(ISNUMBER(C16),C16*180/PI(),"") | Q16: =IF(ISNUMBER(E16),E16*1000,"") | R16: =IF(ISNUMBER(F16),F16*1000,"") | S16: =IF(OR(AND(ISNUMBER(G16),G16<0),AND(ISNUMBER(H16),H16<0)),"VIOLATED - later response unreliable",IF(COUNT(G16:H16)=2,"No negative predicted (estimate)","Not entered / incomplete")) -> Not entered / incomplete
A17: RUN-012 | O17: =IF(ISNUMBER(B17),B17*1000,"") | P17: =IF(ISNUMBER(C17),C17*180/PI(),"") | Q17: =IF(ISNUMBER(E17),E17*1000,"") | R17: =IF(ISNUMBER(F17),F17*1000,"") | S17: =IF(OR(AND(ISNUMBER(G17),G17<0),AND(ISNUMBER(H17),H17<0)),"VIOLATED - later response unreliable",IF(COUNT(G17:H17)=2,"No negative predicted (estimate)","Not entered / incomplete")) -> Not entered / incomplete
A18: RUN-013 | O18: =IF(ISNUMBER(B18),B18*1000,"") | P18: =IF(ISNUMBER(C18),C18*180/PI(),"") | Q18: =IF(ISNUMBER(E18),E18*1000,"") | R18: =IF(ISNUMBER(F18),F18*1000,"") | S18: =IF(OR(AND(ISNUMBER(G18),G18<0),AND(ISNUMBER(H18),H18<0)),"VIOLATED - later response unreliable",IF(COUNT(G18:H18)=2,"No negative predicted (estimate)","Not entered / incomplete")) -> Not entered / incomplete
... A205: RUN-200 | O205: =IF(ISNUMBER(B205),B205*1000,"") | P205: =IF(ISNUMBER(C205),C205*180/PI(),"") | Q205: =IF(ISNUMBER(E205),E205*1000,"") | R205: =IF(ISNUMBER(F205),F205*1000,"") | S205: =IF(OR(AND(ISNUMBER(G205),G205<0),AND(ISNUMBER(H205),H205<0)),"VIOLATED - later response unreliable",IF(COUNT(G205:H205)=2,"No negative predicted (estimate)","Not entered / incomplete")) -> Not entered / incomplete

Sheet Compare
A1: COMPARE TWO ITERATIONS
A2: Select Run A and Run B below. Differences are B minus A. Check loading, road, speed, duration, and validity before attributing a change to one parameter. Blank means unknown; it is not zero.
B4: Run A | D4: Run B
B5: RUN-001 | D5: RUN-002
A7: Input / output | B7: Run A | C7: Units | D7: Run B | E7: Difference (B − A) | F7: How to interpret
A8: CONTEXT — make comparisons fair
A9: Run name | B9: =IFERROR(IF(COUNTIFS('Run Index'!$A$6:$A$205,$B$5,'Run Index'!$B$6:$B$205,"<>")=0,"",INDEX('Run Index'!$B$6:$B$205,MATCH($B$5,'Run Index'!$A$6:$A$205,0))),"") | D9: =IFERROR(IF(COUNTIFS('Run Index'!$A$6:$A$205,$D$5,'Run Index'!$B$6:$B$205,"<>")=0,"",INDEX('Run Index'!$B$6:$B$205,MATCH($D$5,'Run Index'!$A$6:$A$205,0))),"") | E9: =IF(AND(ISNUMBER(B9),ISNUMBER(D9)),D9-B9,"") | F9: Template rows are not completed simulations.
A10: Record type | B10: =IFERROR(IF(COUNTIFS('Run Index'!$A$6:$A$205,$B$5,'Run Index'!$E$6:$E$205,"<>")=0,"",INDEX('Run Index'!$E$6:$E$205,MATCH($B$5,'Run Index'!$A$6:$A$205,0))),"") | D10: =IFERROR(IF(COUNTIFS('Run Index'!$A$6:$A$205,$D$5,'Run Index'!$E$6:$E$205,"<>")=0,"",INDEX('Run Index'!$E$6:$E$205,MATCH($D$5,'Run Index'!$A$6:$A$205,0))),"") | E10: =IF(AND(ISNUMBER(B10),ISNUMBER(D10)),D10-B10,"") | F10: Simulation and physical test are different evidence.
A11: What changed? | B11: =IFERROR(IF(COUNTIFS('Run Index'!$A$6:$A$205,$B$5,'Run Index'!$G$6:$G$205,"<>")=0,"",INDEX('Run Index'!$G$6:$G$205,MATCH($B$5,'Run Index'!$A$6:$A$205,0))),"") | D11: =IFERROR(IF(COUNTIFS('Run Index'!$A$6:$A$205,$D$5,'Run Index'!$G$6:$G$205,"<>")=0,"",INDEX('Run Index'!$G$6:$G$205,MATCH($D$5,'Run Index'!$A$6:$A$205,0))),"") | E11: =IF(AND(ISNUMBER(B11),ISNUMBER(D11)),D11-B11,"") | F11: Change one variable for a controlled comparison.
A12: Code version | B12: =IFERROR(IF(COUNTIFS('Run Index'!$A$6:$A$205,$B$5,'Run Index'!$I$6:$I$205,"<>")=0,"",INDEX('Run Index'!$I$6:$I$205,MATCH($B$5,'Run Index'!$A$6:$A$205,0))),"") | D12: =IFERROR(IF(COUNTIFS('Run Index'!$A$6:$A$205,$D$5,'Run Index'!$I$6:$I$205,"<>")=0,"",INDEX('Run Index'!$I$6:$I$205,MATCH($D$5,'Run Index'!$A$6:$A$205,0))),"") | E12: =IF(AND(ISNUMBER(B12),ISNUMBER(D12)),D12-B12,"") | F12: Record edited inputs as well as the commit.
A13: Driver / fuel / payload | B13: =IFERROR(IF(COUNTIFS('Run Index'!$A$6:$A$205,$B$5,'Run Index'!$J$6:$J$205,"<>")=0,"",INDEX('Run Index'!$J$6:$J$205,MATCH($B$5,'Run Index'!$A$6:$A$205,0))),"") | D13: =IFERROR(IF(COUNTIFS('Run Index'!$A$6:$A$205,$D$5,'Run Index'!$J$6:$J$205,"<>")=0,"",INDEX('Run Index'!$J$6:$J$205,MATCH($D$5,'Run Index'!$A$6:$A$205,0))),"") | E13: =IF(AND(ISNUMBER(B13),ISNUMBER(D13)),D13-B13,"") | F13: Use a consistent loading condition.
A14: Parameter uncertainty | B14: =IFERROR(IF(COUNTIFS('Run Index'!$A$6:$A$205,$B$5,'Run Index'!$K$6:$K$205,"<>")=0,"",INDEX('Run Index'!$K$6:$K$205,MATCH($B$5,'Run Index'!$A$6:$A$205,0))),"") | D14: =IFERROR(IF(COUNTIFS('Run Index'!$A$6:$A$205,$D$5,'Run Index'!$K$6:$K$205,"<>")=0,"",INDEX('Run Index'!$K$6:$K$205,MATCH($D$5,'Run Index'!$A$6:$A$205,0))),"") | E14: =IF(AND(ISNUMBER(B14),ISNUMBER(D14)),D14-B14,"") | F14: Measured vs estimated affects confidence.
A15: VEHICLE INPUTS — wheel-equivalent suspension properties
A16: Mass convention | B16: =IFERROR(IF(COUNTIFS('Vehicle Inputs'!$A$6:$A$205,$B$5,'Vehicle Inputs'!$B$6:$B$205,"<>")=0,"",INDEX('Vehicle Inputs'!$B$6:$B$205,MATCH($B$5,'Vehicle Inputs'!$A$6:$A$205,0))),"") | D16: =IFERROR(IF(COUNTIFS('Vehicle Inputs'!$A$6:$A$205,$D$5,'Vehicle Inputs'!$B$6:$B$205,"<>")=0,"",INDEX('Vehicle Inputs'!$B$6:$B$205,MATCH($D$5,'Vehicle Inputs'!$A$6:$A$205,0))),"") | E16: =IF(AND(ISNUMBER(B16),ISNUMBER(D16)),D16-B16,"") | F16: One-side vs axle-equivalent must be consistent.
A17: Sprung mass | B17: =IFERROR(IF(COUNTIFS('Vehicle Inputs'!$A$6:$A$205,$B$5,'Vehicle Inputs'!$C$6:$C$205,"<>")=0,"",INDEX('Vehicle Inputs'!$C$6:$C$205,MATCH($B$5,'Vehicle Inputs'!$A$6:$A$205,0))),"") | C17: kg | D17: =IFERROR(IF(COUNTIFS('Vehicle Inputs'!$A$6:$A$205,$D$5,'Vehicle Inputs'!$C$6:$C$205,"<>")=0,"",INDEX('Vehicle Inputs'!$C$6:$C$205,MATCH($D$5,'Vehicle Inputs'!$A$6:$A$205,0))),"") | E17: =IF(AND(ISNUMBER(B17),ISNUMBER(D17)),D17-B17,"") | F17: Excludes unsprung mass; includes the chosen driver/payload.
A18: Front unsprung mass | B18: =IFERROR(IF(COUNTIFS('Vehicle Inputs'!$A$6:$A$205,$B$5,'Vehicle Inputs'!$D$6:$D$205,"<>")=0,"",INDEX('Vehicle Inputs'!$D$6:$D$205,MATCH($B$5,'Vehicle Inputs'!$A$6:$A$205,0))),"") | C18: kg | D18: =IFERROR(IF(COUNTIFS('Vehicle Inputs'!$A$6:$A$205,$D$5,'Vehicle Inputs'!$D$6:$D$205,"<>")=0,"",INDEX('Vehicle Inputs'!$D$6:$D$205,MATCH($D$5,'Vehicle Inputs'!$A$6:$A$205,0))),"") | E18: =IF(AND(ISNUMBER(B18),ISNUMBER(D18)),D18-B18,"") | F18: Effective represented mass.
A19: Rear unsprung mass | B19: =IFERROR(IF(COUNTIFS('Vehicle Inputs'!$A$6:$A$205,$B$5,'Vehicle Inputs'!$E$6:$E$205,"<>")=0,"",INDEX('Vehicle Inputs'!$E$6:$E$205,MATCH($B$5,'Vehicle Inputs'!$A$6:$A$205,0))),"") | C19: kg | D19: =IFERROR(IF(COUNTIFS('Vehicle Inputs'!$A$6:$A$205,$D$5,'Vehicle Inputs'!$E$6:$E$205,"<>")=0,"",INDEX('Vehicle Inputs'!$E$6:$E$205,MATCH($D$5,'Vehicle Inputs'!$A$6:$A$205,0))),"") | E19: =IF(AND(ISNUMBER(B19),ISNUMBER(D19)),D19-B19,"") | F19: Effective represented mass.
A20: Sprung pitch inertia | B20: =IFERROR(IF(COUNTIFS('Vehicle Inputs'!$A$6:$A$205,$B$5,'Vehicle Inputs'!$F$6:$F$205,"<>")=0,"",INDEX('Vehicle Inputs'!$F$6:$F$205,MATCH($B$5,'Vehicle Inputs'!$A$6:$A$205,0))),"") | C20: kg m^2 | D20: =IFERROR(IF(COUNTIFS('Vehicle Inputs'!$A$6:$A$205,$D$5,'Vehicle Inputs'!$F$6:$F$205,"<>")=0,"",INDEX('Vehicle Inputs'!$F$6:$F$205,MATCH($D$5,'Vehicle Inputs'!$A$6:$A$205,0))),"") | E20: =IF(AND(ISNUMBER(B20),ISNUMBER(D20)),D20-B20,"") | F20: Not determined from CG location.
A21: CG to front axle | B21: =IFERROR(IF(COUNTIFS('Vehicle Inputs'!$A$6:$A$205,$B$5,'Vehicle Inputs'!$G$6:$G$205,"<>")=0,"",INDEX('Vehicle Inputs'!$G$6:$G$205,MATCH($B$5,'Vehicle Inputs'!$A$6:$A$205,0))),"") | C21: m | D21: =IFERROR(IF(COUNTIFS('Vehicle Inputs'!$A$6:$A$205,$D$5,'Vehicle Inputs'!$G$6:$G$205,"<>")=0,"",INDEX('Vehicle Inputs'!$G$6:$G$205,MATCH($D$5,'Vehicle Inputs'!$A$6:$A$205,0))),"") | E21: =IF(AND(ISNUMBER(B21),ISNUMBER(D21)),D21-B21,"") | F21: Use sprung-body CG.
A22: CG to rear axle | B22: =IFERROR(IF(COUNTIFS('Vehicle Inputs'!$A$6:$A$205,$B$5,'Vehicle Inputs'!$H$6:$H$205,"<>")=0,"",INDEX('Vehicle Inputs'!$H$6:$H$205,MATCH($B$5,'Vehicle Inputs'!$A$6:$A$205,0))),"") | C22: m | D22: =IFERROR(IF(COUNTIFS('Vehicle Inputs'!$A$6:$A$205,$D$5,'Vehicle Inputs'!$H$6:$H$205,"<>")=0,"",INDEX('Vehicle Inputs'!$H$6:$H$205,MATCH($D$5,'Vehicle Inputs'!$A$6:$A$205,0))),"") | E22: =IF(AND(ISNUMBER(B22),ISNUMBER(D22)),D22-B22,"") | F22: Use sprung-body CG.
A23: Front wheel rate | B23: =IFERROR(IF(COUNTIFS('Vehicle Inputs'!$A$6:$A$205,$B$5,'Vehicle Inputs'!$I$6:$I$205,"<>")=0,"",INDEX('Vehicle Inputs'!$I$6:$I$205,MATCH($B$5,'Vehicle Inputs'!$A$6:$A$205,0))),"") | C23: N/m | D23: =IFERROR(IF(COUNTIFS('Vehicle Inputs'!$A$6:$A$205,$D$5,'Vehicle Inputs'!$I$6:$I$205,"<>")=0,"",INDEX('Vehicle Inputs'!$I$6:$I$205,MATCH($D$5,'Vehicle Inputs'!$A$6:$A$205,0))),"") | E23: =IF(AND(ISNUMBER(B23),ISNUMBER(D23)),D23-B23,"") | F23: Coil-spring rate times spring motion ratio squared.
A24: Rear wheel rate | B24: =IFERROR(IF(COUNTIFS('Vehicle Inputs'!$A$6:$A$205,$B$5,'Vehicle Inputs'!$J$6:$J$205,"<>")=0,"",INDEX('Vehicle Inputs'!$J$6:$J$205,MATCH($B$5,'Vehicle Inputs'!$A$6:$A$205,0))),"") | C24: N/m | D24: =IFERROR(IF(COUNTIFS('Vehicle Inputs'!$A$6:$A$205,$D$5,'Vehicle Inputs'!$J$6:$J$205,"<>")=0,"",INDEX('Vehicle Inputs'!$J$6:$J$205,MATCH($D$5,'Vehicle Inputs'!$A$6:$A$205,0))),"") | E24: =IF(AND(ISNUMBER(B24),ISNUMBER(D24)),D24-B24,"") | F24: Coil-spring rate times spring motion ratio squared.
A25: Front wheel damping | B25: =IFERROR(IF(COUNTIFS('Vehicle Inputs'!$A$6:$A$205,$B$5,'Vehicle Inputs'!$K$6:$K$205,"<>")=0,"",INDEX('Vehicle Inputs'!$K$6:$K$205,MATCH($B$5,'Vehicle Inputs'!$A$6:$A$205,0))),"") | C25: N s/m | D25: =IFERROR(IF(COUNTIFS('Vehicle Inputs'!$A$6:$A$205,$D$5,'Vehicle Inputs'!$K$6:$K$205,"<>")=0,"",INDEX('Vehicle Inputs'!$K$6:$K$205,MATCH($D$5,'Vehicle Inputs'!$A$6:$A$205,0))),"") | E25: =IF(AND(ISNUMBER(B25),ISNUMBER(D25)),D25-B25,"") | F25: Damper coefficient times damper motion ratio squared.
A26: Rear wheel damping | B26: =IFERROR(IF(COUNTIFS('Vehicle Inputs'!$A$6:$A$205,$B$5,'Vehicle Inputs'!$L$6:$L$205,"<>")=0,"",INDEX('Vehicle Inputs'!$L$6:$L$205,MATCH($B$5,'Vehicle Inputs'!$A$6:$A$205,0))),"") | C26: N s/m | D26: =IFERROR(IF(COUNTIFS('Vehicle Inputs'!$A$6:$A$205,$D$5,'Vehicle Inputs'!$L$6:$L$205,"<>")=0,"",INDEX('Vehicle Inputs'!$L$6:$L$205,MATCH($D$5,'Vehicle Inputs'!$A$6:$A$205,0))),"") | E26: =IF(AND(ISNUMBER(B26),ISNUMBER(D26)),D26-B26,"") | F26: More damping is not automatically better.
A27: Front tire stiffness | B27: =IFERROR(IF(COUNTIFS('Vehicle Inputs'!$A$6:$A$205,$B$5,'Vehicle Inputs'!$M$6:$M$205,"<>")=0,"",INDEX('Vehicle Inputs'!$M$6:$M$205,MATCH($B$5,'Vehicle Inputs'!$A$6:$A$205,0))),"") | C27: N/m | D27: =IFERROR(IF(COUNTIFS('Vehicle Inputs'!$A$6:$A$205,$D$5,'Vehicle Inputs'!$M$6:$M$205,"<>")=0,"",INDEX('Vehicle Inputs'!$M$6:$M$205,MATCH($D$5,'Vehicle Inputs'!$A$6:$A$205,0))),"") | E27: =IF(AND(ISNUMBER(B27),ISNUMBER(D27)),D27-B27,"") | F27: Pressure/load-dependent assumption.
A28: Rear tire stiffness | B28: =IFERROR(IF(COUNTIFS('Vehicle Inputs'!$A$6:$A$205,$B$5,'Vehicle Inputs'!$N$6:$N$205,"<>")=0,"",INDEX('Vehicle Inputs'!$N$6:$N$205,MATCH($B$5,'Vehicle Inputs'!$A$6:$A$205,0))),"") | C28: N/m | D28: =IFERROR(IF(COUNTIFS('Vehicle Inputs'!$A$6:$A$205,$D$5,'Vehicle Inputs'!$N$6:$N$205,"<>")=0,"",INDEX('Vehicle Inputs'!$N$6:$N$205,MATCH($D$5,'Vehicle Inputs'!$A$6:$A$205,0))),"") | E28: =IF(AND(ISNUMBER(B28),ISNUMBER(D28)),D28-B28,"") | F28: Pressure/load-dependent assumption.
A29: Front tire pressure | B29: =IFERROR(IF(COUNTIFS('Vehicle Inputs'!$A$6:$A$205,$B$5,'Vehicle Inputs'!$O$6:$O$205,"<>")=0,"",INDEX('Vehicle Inputs'!$O$6:$O$205,MATCH($B$5,'Vehicle Inputs'!$A$6:$A$205,0))),"") | C29: kPa | D29: =IFERROR(IF(COUNTIFS('Vehicle Inputs'!$A$6:$A$205,$D$5,'Vehicle Inputs'!$O$6:$O$205,"<>")=0,"",INDEX('Vehicle Inputs'!$O$6:$O$205,MATCH($D$5,'Vehicle Inputs'!$A$6:$A$205,0))),"") | E29: =IF(AND(ISNUMBER(B29),ISNUMBER(D29)),D29-B29,"") | F29: Record the test condition.
A30: Rear tire pressure | B30: =IFERROR(IF(COUNTIFS('Vehicle Inputs'!$A$6:$A$205,$B$5,'Vehicle Inputs'!$P$6:$P$205,"<>")=0,"",INDEX('Vehicle Inputs'!$P$6:$P$205,MATCH($B$5,'Vehicle Inputs'!$A$6:$A$205,0))),"") | C30: kPa | D30: =IFERROR(IF(COUNTIFS('Vehicle Inputs'!$A$6:$A$205,$D$5,'Vehicle Inputs'!$P$6:$P$205,"<>")=0,"",INDEX('Vehicle Inputs'!$P$6:$P$205,MATCH($D$5,'Vehicle Inputs'!$A$6:$A$205,0))),"") | E30: =IF(AND(ISNUMBER(B30),ISNUMBER(D30)),D30-B30,"") | F30: Record the test condition.
A31: ROAD & NUMERICAL SETTINGS — verify the same disturbance
A32: Vehicle speed | B32: =IFERROR(IF(COUNTIFS('Road and Solver'!$A$6:$A$205,$B$5,'Road and Solver'!$B$6:$B$205,"<>")=0,"",INDEX('Road and Solver'!$B$6:$B$205,MATCH($B$5,'Road and Solver'!$A$6:$A$205,0))),"") | C32: m/s | D32: =IFERROR(IF(COUNTIFS('Road and Solver'!$A$6:$A$205,$D$5,'Road and Solver'!$B$6:$B$205,"<>")=0,"",INDEX('Road and Solver'!$B$6:$B$205,MATCH($D$5,'Road and Solver'!$A$6:$A$205,0))),"") | E32: =IF(AND(ISNUMBER(B32),ISNUMBER(D32)),D32-B32,"") | F32: Changes crossing time and axle delay.
A33: Bump shape | B33: =IFERROR(IF(COUNTIFS('Road and Solver'!$A$6:$A$205,$B$5,'Road and Solver'!$C$6:$C$205,"<>")=0,"",INDEX('Road and Solver'!$C$6:$C$205,MATCH($B$5,'Road and Solver'!$A$6:$A$205,0))),"") | D33: =IFERROR(IF(COUNTIFS('Road and Solver'!$A$6:$A$205,$D$5,'Road and Solver'!$C$6:$C$205,"<>")=0,"",INDEX('Road and Solver'!$C$6:$C$205,MATCH($D$5,'Road and Solver'!$A$6:$A$205,0))),"") | E33: =IF(AND(ISNUMBER(B33),ISNUMBER(D33)),D33-B33,"") | F33: Smooth cosine or original half ellipse.
A34: Consecutive bumps | B34: =IFERROR(IF(COUNTIFS('Road and Solver'!$A$6:$A$205,$B$5,'Road and Solver'!$D$6:$D$205,"<>")=0,"",INDEX('Road and Solver'!$D$6:$D$205,MATCH($B$5,'Road and Solver'!$A$6:$A$205,0))),"") | C34: yes / no | D34: =IFERROR(IF(COUNTIFS('Road and Solver'!$A$6:$A$205,$D$5,'Road and Solver'!$D$6:$D$205,"<>")=0,"",INDEX('Road and Solver'!$D$6:$D$205,MATCH($D$5,'Road and Solver'!$A$6:$A$205,0))),"") | E34: =IF(AND(ISNUMBER(B34),ISNUMBER(D34)),D34-B34,"") | F34: Inspect the Bumps sheet for per-bump dimensions.
A35: Bump count | B35: =IFERROR(IF(COUNTIFS('Road and Solver'!$A$6:$A$205,$B$5,'Road and Solver'!$Q$6:$Q$205,"<>")=0,"",INDEX('Road and Solver'!$Q$6:$Q$205,MATCH($B$5,'Road and Solver'!$A$6:$A$205,0))),"") | D35: =IFERROR(IF(COUNTIFS('Road and Solver'!$A$6:$A$205,$D$5,'Road and Solver'!$Q$6:$Q$205,"<>")=0,"",INDEX('Road and Solver'!$Q$6:$Q$205,MATCH($D$5,'Road and Solver'!$A$6:$A$205,0))),"") | E35: =IF(AND(ISNUMBER(B35),ISNUMBER(D35)),D35-B35,"") | F35: Number of rows with height and width supplied.
A36: Requested simulation step | B36: =IFERROR(IF(COUNTIFS('Road and Solver'!$A$6:$A$205,$B$5,'Road and Solver'!$E$6:$E$205,"<>")=0,"",INDEX('Road and Solver'!$E$6:$E$205,MATCH($B$5,'Road and Solver'!$A$6:$A$205,0))),"") | C36: s | D36: =IFERROR(IF(COUNTIFS('Road and Solver'!$A$6:$A$205,$D$5,'Road and Solver'!$E$6:$E$205,"<>")=0,"",INDEX('Road and Solver'!$E$6:$E$205,MATCH($D$5,'Road and Solver'!$A$6:$A$205,0))),"") | E36: =IF(AND(ISNUMBER(B36),ISNUMBER(D36)),D36-B36,"") | F36: Smaller time step should be checked for convergence.
A37: Actual simulation step | B37: =IFERROR(IF(COUNTIFS('Road and Solver'!$A$6:$A$205,$B$5,'Road and Solver'!$F$6:$F$205,"<>")=0,"",INDEX('Road and Solver'!$F$6:$F$205,MATCH($B$5,'Road and Solver'!$A$6:$A$205,0))),"") | C37: s | D37: =IFERROR(IF(COUNTIFS('Road and Solver'!$A$6:$A$205,$D$5,'Road and Solver'!$F$6:$F$205,"<>")=0,"",INDEX('Road and Solver'!$F$6:$F$205,MATCH($D$5,'Road and Solver'!$A$6:$A$205,0))),"") | E37: =IF(AND(ISNUMBER(B37),ISNUMBER(D37)),D37-B37,"") | F37: Copy the actual MATLAB time spacing.
A38: Actual end time | B38: =IFERROR(IF(COUNTIFS('Road and Solver'!$A$6:$A$205,$B$5,'Road and Solver'!$H$6:$H$205,"<>")=0,"",INDEX('Road and Solver'!$H$6:$H$205,MATCH($B$5,'Road and Solver'!$A$6:$A$205,0))),"") | C38: s | D38: =IFERROR(IF(COUNTIFS('Road and Solver'!$A$6:$A$205,$D$5,'Road and Solver'!$H$6:$H$205,"<>")=0,"",INDEX('Road and Solver'!$H$6:$H$205,MATCH($D$5,'Road and Solver'!$A$6:$A$205,0))),"") | E38: =IF(AND(ISNUMBER(B38),ISNUMBER(D38)),D38-B38,"") | F38: Duration affects whole-run RMS.
A39: Post-bump time | B39: =IFERROR(IF(COUNTIFS('Road and Solver'!$A$6:$A$205,$B$5,'Road and Solver'!$I$6:$I$205,"<>")=0,"",INDEX('Road and Solver'!$I$6:$I$205,MATCH($B$5,'Road and Solver'!$A$6:$A$205,0))),"") | C39: s | D39: =IFERROR(IF(COUNTIFS('Road and Solver'!$A$6:$A$205,$D$5,'Road and Solver'!$I$6:$I$205,"<>")=0,"",INDEX('Road and Solver'!$I$6:$I$205,MATCH($D$5,'Road and Solver'!$A$6:$A$205,0))),"") | E39: =IF(AND(ISNUMBER(B39),ISNUMBER(D39)),D39-B39,"") | F39: Compare consistent settling intervals.
A40: Relative convergence tolerance | B40: =IFERROR(IF(COUNTIFS('Road and Solver'!$A$6:$A$205,$B$5,'Road and Solver'!$K$6:$K$205,"<>")=0,"",INDEX('Road and Solver'!$K$6:$K$205,MATCH($B$5,'Road and Solver'!$A$6:$A$205,0))),"") | C40: fraction | D40: =IFERROR(IF(COUNTIFS('Road and Solver'!$A$6:$A$205,$D$5,'Road and Solver'!$K$6:$K$205,"<>")=0,"",INDEX('Road and Solver'!$K$6:$K$205,MATCH($D$5,'Road and Solver'!$A$6:$A$205,0))),"") | E40: =IF(AND(ISNUMBER(B40),ISNUMBER(D40)),D40-B40,"") | F40: 0.01 means 1%, not 0.01%.
A41: Absolute tolerances | B41: =IFERROR(IF(COUNTIFS('Road and Solver'!$A$6:$A$205,$B$5,'Road and Solver'!$L$6:$L$205,"<>")=0,"",INDEX('Road and Solver'!$L$6:$L$205,MATCH($B$5,'Road and Solver'!$A$6:$A$205,0))),"") | C41: mixed | D41: =IFERROR(IF(COUNTIFS('Road and Solver'!$A$6:$A$205,$D$5,'Road and Solver'!$L$6:$L$205,"<>")=0,"",INDEX('Road and Solver'!$L$6:$L$205,MATCH($D$5,'Road and Solver'!$A$6:$A$205,0))),"") | E41: =IF(AND(ISNUMBER(B41),ISNUMBER(D41)),D41-B41,"") | F41: Retain the metric order and units.
A42: Initial flat length | B42: =IFERROR(IF(COUNTIFS('Road and Solver'!$A$6:$A$205,$B$5,'Road and Solver'!$M$6:$M$205,"<>")=0,"",INDEX('Road and Solver'!$M$6:$M$205,MATCH($B$5,'Road and Solver'!$A$6:$A$205,0))),"") | C42: m | D42: =IFERROR(IF(COUNTIFS('Road and Solver'!$A$6:$A$205,$D$5,'Road and Solver'!$M$6:$M$205,"<>")=0,"",INDEX('Road and Solver'!$M$6:$M$205,MATCH($D$5,'Road and Solver'!$A$6:$A$205,0))),"") | E42: =IF(AND(ISNUMBER(B42),ISNUMBER(D42)),D42-B42,"") | F42: Defines initial road geometry.
...

Sheet Graph Gallery
B2: GRAPH GALLERY / OPTIONAL SCREENSHOTS
B5: Paste dashboard screenshots here using Excel Insert → Pictures. Put the run ID, code version and conclusion beside each image. Images are manually managed; use Run Index paths to keep links for all runs. Duplicating this sheet creates more space.
B10: Run ID: __________ Code version: __________ What changed: ____________________
B12: INSERT DASHBOARD SCREENSHOT HERE
B30: Interpretation / trade-off: ___________________________________________________________
B35: Run ID: __________ Code version: __________ What changed: ____________________
B37: INSERT DASHBOARD SCREENSHOT HERE
B55: Interpretation / trade-off: ___________________________________________________________

Sheet Field Guide
A1: FIELD GUIDE
A2: Header comments give input guidance. This sheet lists every field and its purpose; engineering definitions are also in the accompanying report.
A5: Sheet | B5: Field | C5: Guidance
A6: Run Index | B6: Run ID | C6: Stable identifier joining the sheets. Keep the ID with the complete row when sorting.
A7: Run Index | B7: Run name | C7: Record enough context to reproduce the run and find its original evidence. Use text or a saved file path as indicated.
A8: Run Index | B8: Date / time (with timezone) | C8: Record enough context to reproduce the run and find its original evidence. Use text or a saved file path as indicated.
A9: Run Index | B9: Owner | C9: Record enough context to reproduce the run and find its original evidence. Use text or a saved file path as indicated.
A10: Run Index | B10: Record type | C10: Record enough context to reproduce the run and find its original evidence. Use text or a saved file path as indicated.
A11: Run Index | B11: Parent / baseline ID | C11: Record enough context to reproduce the run and find its original evidence. Use text or a saved file path as indicated.
A12: Run Index | B12: What changed? | C12: Record enough context to reproduce the run and find its original evidence. Use text or a saved file path as indicated.
A13: Run Index | B13: Hypothesis / expected effect | C13: Record enough context to reproduce the run and find its original evidence. Use text or a saved file path as indicated.
A14: Run Index | B14: Code commit / version | C14: Record the actual commit plus any uncommitted parameter changes. A commit alone does not capture edited inputs. All input sheets should preserve the exact values used.
A15: Run Index | B15: Driver / fuel / payload condition | C15: Record enough context to reproduce the run and find its original evidence. Use text or a saved file path as indicated.
A16: Run Index | B16: Parameter source / uncertainty | C16: Record enough context to reproduce the run and find its original evidence. Use text or a saved file path as indicated.
... A89: Outputs | B89: Contact screen (calculated) | C89: Record the actual setting used by MATLAB. Grey fields are calculated. Consult the script comments and report for definitions.
